测试开始了
测试报错了
测试数据
测试结束
测试开始了
测试报错了
测试数据
测试结束
2019-05-04 19:05:15,872- root -INFO -测试开始了 - [logger.py:19]
2019-05-04 19:05:15,873- root -ERROR -测试报错了 - [logger.py:20]
2019-05-04 19:05:15,874- root -DEBUG -测试数据 - [logger.py:21]
2019-05-04 19:05:15,875- root -INFO -测试结束 - [logger.py:22]
2019-05-04 19:07:03,079- case -INFO -测试开始了 - [logger.py:20]
2019-05-04 19:07:03,080- case -ERROR -测试报错了 - [logger.py:21]
2019-05-04 19:07:03,080- case -DEBUG -测试数据 - [logger.py:22]
2019-05-04 19:07:03,080- case -INFO -测试结束 - [logger.py:23]
2019-05-04 19:09:52,543- case -INFO -测试开始了 - [logger.py:24]
2019-05-04 19:09:52,543- case -ERROR -测试报错了 - [logger.py:25]
2019-05-04 19:09:52,544- case -DEBUG -测试数据 - [logger.py:26]
2019-05-04 19:09:52,544- case -INFO -测试结束 - [logger.py:27]
2019-05-04 19:10:02,550- case -INFO -测试开始了 - [logger.py:24]
2019-05-04 19:10:02,553- case -ERROR -测试报错了 - [logger.py:25]
2019-05-04 19:10:02,553- case -DEBUG -测试数据 - [logger.py:26]
2019-05-04 19:10:02,553- case -INFO -测试结束 - [logger.py:27]
